2019-11-19 17:24:23,217 file.manager INFO 1.2.0
2019-11-19 17:24:23,219 file.manager INFO Copyright (C) 2003-2010
2019-11-19 17:24:23,219 file.manager INFO   Noriaki Ando
2019-11-19 17:24:23,220 file.manager INFO   Intelligent Systems Research Institute, AIST
2019-11-19 17:24:23,220 file.manager INFO Manager starting.
2019-11-19 17:24:23,220 file.manager INFO Starting local logging.
2019-11-19 17:24:23,227 file.manager.namingmanager INFO NameServer connection succeeded: corba/localhost
2019-11-19 17:24:25,266 file.ManagerServant INFO Master manager not found
2019-11-19 17:24:25,275 file.LocalServiceAdmin INFO All the local services are enabled.
2019-11-19 17:24:25,276 file.LocalServiceAdmin INFO All the local services are enabled.
2019-11-19 17:24:25,306 file.manager INFO Component type conf file: Human_Tracking_py.conf loaded.
2019-11-19 17:24:25,325 file.ec_base INFO setRate(1000000.000000) done
2019-11-19 17:24:25,326 file.ec_base INFO setRate(10.000000) done
2019-11-19 17:24:25,334 file.rtobject INFO 1 execution context was created.
2019-11-19 17:24:25,352 file.rtobject INFO Initial active configuration set is default.
2019-11-19 17:24:29,148 file.SdoServiceAdmin WARNING No available SDO service in the factory: 
2019-11-19 17:24:29,151 file.SdoServiceAdmin ERROR type  already exists.
2019-11-19 17:24:37,420 file.ManagerServant INFO Master manager not found
2019-11-19 17:24:49,663 file.ManagerServant INFO Master manager not found
2019-11-19 17:25:01,921 file.ManagerServant INFO Master manager not found
2019-11-19 17:25:03,808 file.rtobject ERROR Traceback (most recent call last):
  File "C:\Python27\lib\site-packages\OpenRTM_aist\RTObject.py", line 1571, in on_execute
    ret = self.onExecute(ec_id)
  File "c:\workspace\Human_Tracking_py\Human_Tracking_py.py", line 176, in onExecute
    a=trans_x_y(self.range_data[i],i)
TypeError: 'NoneType' object is not callable

2019-11-19 17:25:03,812 file.rtobject ERROR Traceback (most recent call last):
  File "C:\Python27\lib\site-packages\OpenRTM_aist\RTObject.py", line 1370, in on_deactivated
    ret = self.onDeactivated(ec_id)
  File "c:\workspace\Human_Tracking_py\Human_Tracking_py.py", line 163, in onDeactivated
    return RTC.RTC_OK
AttributeError: 'NoneType' object has no attribute 'RTC_OK'

2019-11-19 17:25:08,108 file.ec_worker ERROR State of the RTC is not ACTIVE_STATE.
2019-11-19 17:25:08,165 file.ec_worker WARNING ExecutionContext is already stopped.
2019-11-19 17:25:08,165 file.ec_base ERROR Invoking on_shutdown() for each RTC failed.
