2019-11-26 05:41:08,442 file.manager INFO 1.2.0
2019-11-26 05:41:08,442 file.manager INFO Copyright (C) 2003-2010
2019-11-26 05:41:08,442 file.manager INFO   Noriaki Ando
2019-11-26 05:41:08,443 file.manager INFO   Intelligent Systems Research Institute, AIST
2019-11-26 05:41:08,443 file.manager INFO Manager starting.
2019-11-26 05:41:08,443 file.manager INFO Starting local logging.
2019-11-26 05:41:08,445 file.manager.namingmanager INFO NameServer connection succeeded: corba/localhost
2019-11-26 05:41:08,456 file.ManagerServant INFO Master manager not found
2019-11-26 05:41:08,459 file.LocalServiceAdmin INFO All the local services are enabled.
2019-11-26 05:41:08,460 file.LocalServiceAdmin INFO All the local services are enabled.
2019-11-26 05:41:08,470 file.manager INFO Component type conf file: Human_Tracking_py.conf loaded.
2019-11-26 05:41:08,475 file.ec_base INFO setRate(1000000.000000) done
2019-11-26 05:41:08,476 file.ec_base INFO setRate(1000.000000) done
2019-11-26 05:41:08,477 file.rtobject INFO 1 execution context was created.
2019-11-26 05:41:08,484 file.rtobject INFO Initial active configuration set is default.
2019-11-26 05:41:13,991 file.SdoServiceAdmin WARNING No available SDO service in the factory: 
2019-11-26 05:41:13,991 file.SdoServiceAdmin ERROR type  already exists.
2019-11-26 05:41:18,571 file.ManagerServant INFO Master manager not found
2019-11-26 05:41:28,649 file.ManagerServant INFO Master manager not found
2019-11-26 05:41:38,719 file.ManagerServant INFO Master manager not found
2019-11-26 05:41:48,790 file.ManagerServant INFO Master manager not found
2019-11-26 05:41:58,862 file.ManagerServant INFO Master manager not found
2019-11-26 05:42:08,933 file.ManagerServant INFO Master manager not found
2019-11-26 05:42:19,001 file.ManagerServant INFO Master manager not found
2019-11-26 05:42:19,212 file.rtobject ERROR Traceback (most recent call last):
  File "/usr/lib/python2.7/dist-packages/OpenRTM_aist/RTObject.py", line 1571, in on_execute
    ret = self.onExecute(ec_id)
  File "/home/soka/workspace/Pocosystems/Human_Tracking_py/Human_Tracking_py.py", line 205, in onExecute
    return RTC.RTC_OK
AttributeError: 'NoneType' object has no attribute 'RTC_OK'

2019-11-26 05:42:19,219 file.rtobject ERROR Traceback (most recent call last):
  File "/usr/lib/python2.7/dist-packages/OpenRTM_aist/RTObject.py", line 1370, in on_deactivated
    ret = self.onDeactivated(ec_id)
  File "/home/soka/workspace/Pocosystems/Human_Tracking_py/Human_Tracking_py.py", line 146, in onDeactivated
    return RTC.RTC_OK
AttributeError: 'NoneType' object has no attribute 'RTC_OK'

2019-11-26 05:42:22,997 file.ec_worker ERROR State of the RTC is not ACTIVE_STATE.
2019-11-26 05:42:23,000 file.ec_worker WARNING ExecutionContext is already stopped.
2019-11-26 05:42:23,001 file.ec_base ERROR Invoking on_shutdown() for each RTC failed.
